Workbook

Sheet Materialstamm
A1: ArtikelNr | B1: Bezeichnung | C1: Größe | D1: Produktgruppe | E1: Materialart | F1: Mengeneinheit | G1: Preis p.u. | H1: ArtikelNr
A2: E00 | B2: Motor | D2: Ersatzteile | E2: ERSA | F2: ST | G2: 2925 | H2: E00
A3: 101236 | B3: Fahrrad Basic 24 | C3: 24 | D3: Fahrräder | E3: FERT | F3: ST | G3: 309.38 | H3: 101236
A4: 101237 | B4: Fahrrad Basic 26 | C4: 26 | D4: Fahrräder | E4: FERT | F4: ST | G4: 315.96 | H4: 101237
A5: 101239 | B5: Fahrrad Basic 28 | C5: 28 | D5: Fahrräder | E5: FERT | F5: ST | G5: 322.74 | H5: 101239
A6: 101238 | B6: Fahrrad Basic 27,5 | C6: 27.5 | D6: Fahrräder | E6: FERT | F6: ST | G6: 320.485 | H6: 101238
A7: 101240 | B7: Fahrrad Basic 29 | C7: 29 | D7: Fahrräder | E7: FERT | F7: ST | G7: 328 | H7: 101240
A8: 101241 | B8: Fahrrad Comfort 24 | C8: 24 | D8: Fahrräder | E8: FERT | F8: ST | G8: 348.32 | H8: 101241
A9: 101242 | B9: Fahrrad Comfort 26 | C9: 26 | D9: Fahrräder | E9: FERT | F9: ST | G9: 357.34 | H9: 101242
A10: 101243 | B10: Fahrrad Comfort 27,5 | C10: 27.5 | D10: Fahrräder | E10: FERT | F10: ST | G10: 363.695 | H10: 101243
A11: 101244 | B11: Fahrrad Comfort 28 | C11: 28 | D11: Fahrräder | E11: FERT | F11: ST | G11: 366.56 | H11: 101244
A12: 101245 | B12: Fahrrad Comfort 29 | C12: 29 | D12: Fahrräder | E12: FERT | F12: ST | G12: 374.26 | H12: 101245
A13: 101246 | B13: Fahrrad Premium 24 | C13: 24 | D13: Fahrräder | E13: FERT | F13: ST | G13: 405.01 | H13: 101246
A14: 101247 | B14: Fahrrad Premium 26 | C14: 26 | D14: Fahrräder | E14: FERT | F14: ST | G14: 415.43 | H14: 101247
... A37: 101265 | B37: Rahmen Premium 29 | C37: 29 | D37: Rahmen | E37: HALB | F37: ST | G37: 221.02 | H37: 101265
A38: 101215 | B38: Aluminiumrohr | D38: Aluminium | E38: ROH | F38: M | G38: 12.7 | H38: 101215
A39: 101276 | B39: Sechskantmutter 5mm | D39: Befestigung | E39: ROH | F39: ST | G39: 0.01 | H39: 101276
A40: 101277 | B40: Sicherungsscheibe 5mm | D40: Befestigung | E40: ROH | F40: ST | G40: 0.01 | H40: 101277
A41: 101223 | B41: Inbusschraube 5x20mm | D41: Befestigung | E41: ROH | F41: ST | G41: 0.02 | H41: 101223
A42: 101216 | B42: Bremsanlage | D42: Bremsen | E42: ROH | F42: ST | G42: 16 | H42: 101216
A43: 101214 | B43: Carbonrohr | D43: Carbon | E43: ROH | F43: M | G43: 24.9 | H43: 101214
A44: 101217 | B44: Felge 24 | C44: 24 | D44: Felge | E44: ROH | F44: ST | G44: 2 | H44: 101217
A45: 101218 | B45: Felge 26 | C45: 26 | D45: Felge | E45: ROH | F45: ST | G45: 2.2 | H45: 101218
A46: 101220 | B46: Felge 28 | C46: 28 | D46: Felge | E46: ROH | F46: ST | G46: 2.4 | H46: 101220
A47: 101219 | B47: Felge 27,5 | C47: 27.5 | D47: Felge | E47: ROH | F47: ST | G47: 2.35 | H47: 101219
A48: 101221 | B48: Felge 29 | C48: 29 | D48: Felge | E48: ROH | F48: ST | G48: 2.5 | H48: 101221
A49: 101222 | B49: Garantiedokument | D49: Garantie | E49: ROH | F49: ST | G49: 0.3 | H49: 101222
A50: 101225 | B50: Kettenschaltung Bauteile | D50: Kette | E50: ROH | F50: ST | G50: 12 | H50: 101225
A51: 101224 | B51: Kette | D51: Kette | E51: ROH | F51: ST | G51: 2 | H51: 101224
A52: 101231 | B52: Lack | D52: Lack | E52: ROH | F52: L | G52: 10 | H52: 101231
A53: 101286 | B53: Lack Superior | D53: Lack | E53: ROH | F53: L | G53: 24 | H53: 101286
A54: 101232 | B54: Lenker Bauteile Basic | D54: Lenker | E54: ROH | F54: ST | G54: 22.5 | H54: 101232
A55: 101233 | B55: Lenker Bauteile Comfort | D55: Lenker | E55: ROH | F55: ST | G55: 23 | H55: 101233
A56: 101234 | B56: Lenker Bauteile Premium | D56: Lenker | E56: ROH | F56: ST | G56: 49 | H56: 101234
A57: 101235 | B57: Pedale Bauteile | D57: Pedale | E57: ROH | F57: ST | G57: 8 | H57: 101235
A58: 101266 | B58: Reifen 24 | C58: 24 | D58: Reifen | E58: ROH | F58: ST | G58: 4 | H58: 101266
A59: 101267 | B59: Reifen 26 | C59: 26 | D59: Reifen | E59: ROH | F59: ST | G59: 4.4 | H59: 101267
A60: 101269 | B60: Reifen 28 | C60: 28 | D60: Reifen | E60: ROH | F60: ST | G60: 4.8 | H60: 101269
A61: 101268 | B61: Reifen 27,5 | C61: 27.5 | D61: Reifen | E61: ROH | F61: ST | G61: 4.7 | H61: 101268
A62: 101270 | B62: Reifen 29 | C62: 29 | D62: Reifen | E62: ROH | F62: ST | G62: 5 | H62: 101270
...

Sheet Tarife
A1: Arbeitsplatz | B1: Leistungsart | C1: Leistungseinheit | D1: Tarif variabel
A2: Reifenmontage | B2: Maschinenarbeit | C2: STD | D2: 10
A3: Reifenmontage | B3: Personalarbeit | C3: STD | D3: 60
A4: Rahmenerstellung | B4: Maschinenarbeit | C4: STD | D4: 26
A5: Rahmenerstellung | B5: Personalarbeit | C5: STD | D5: 60
A6: Fahrradmontage | B6: Maschinenarbeit | C6: STD | D6: 28
A7: Fahrradmontage | B7: Personalarbeit | C7: STD | D7: 60

Sheet bewert. Stücklisten Räder
C1: Bez | D1: ArtNr | E1: Menge | F1: ME | G1: Preis | H1: Herstellkosten
A2: 101226 | B2: Komplettrad 24 | H2: 30.1
C3: Reifen 24 | D3: =VLOOKUP(C3,Materialstamm!B:H,7,0) -> 101266 | E3: 1 | F3: ST | G3: 4 | H3: 4
C4: Speichen 24 | D4: =VLOOKUP(C4,Materialstamm!B:H,7,0) -> 101281 | E4: 36 | F4: ST | G4: 0.2 | H4: 7.2
C5: Schlauch 24 | D5: =VLOOKUP(C5,Materialstamm!B:H,7,0) -> 101271 | E5: 1 | F5: ST | G5: 1.9 | H5: 1.9
C6: Felge 24 | D6: =VLOOKUP(C6,Materialstamm!B:H,7,0) -> 101217 | E6: 1 | F6: ST | G6: 2 | H6: 2
C7: Maschinenarbeit | D7: Reifenmontage | E7: 0.15 | F7: STD | G7: 10 | H7: 1.5
C8: Personenarbeit | D8: Reifenmontage | E8: 0.225 | F8: STD | G8: 60 | H8: 13.5
A10: 101227 | B10: Komplettrad 26 | H10: 31.62
C11: Reifen 26 | D11: =VLOOKUP(C11,Materialstamm!B:H,7,0) -> 101267 | E11: 1 | F11: ST | G11: 4.4 | H11: 4.4
C12: Speichen 26 | D12: =VLOOKUP(C12,Materialstamm!B:H,7,0) -> 101282 | E12: 36 | F12: ST | G12: 0.22 | H12: 7.92
C13: Schlauch 26 | D13: =VLOOKUP(C13,Materialstamm!B:H,7,0) -> 101272 | E13: 1 | F13: ST | G13: 2.1 | H13: 2.1
C14: Felge 26 | D14: =VLOOKUP(C14,Materialstamm!B:H,7,0) -> 101218 | E14: 1 | F14: ST | G14: 2.2 | H14: 2.2
C15: Maschinenarbeit | D15: Reifenmontage | E15: 0.15 | F15: STD | G15: 10 | H15: 1.5
C16: Personenarbeit | D16: Reifenmontage | E16: 0.225 | F16: STD | G16: 60 | H16: 13.5
A18: 101229 | B18: Komplettrad 28 | H18: 33.24
C19: Reifen 28 | D19: =VLOOKUP(C19,Materialstamm!B:H,7,0) -> 101269 | E19: 1 | F19: ST | G19: 4.8 | H19: 4.8
C20: Speichen 28 | D20: =VLOOKUP(C20,Materialstamm!B:H,7,0) -> 101284 | E20: 36 | F20: ST | G20: 0.24 | H20: 8.64
C21: Schlauch 28 | D21: =VLOOKUP(C21,Materialstamm!B:H,7,0) -> 101274 | E21: 1 | F21: ST | G21: 2.4 | H21: 2.4
C22: Felge 28 | D22: =VLOOKUP(C22,Materialstamm!B:H,7,0) -> 101220 | E22: 1 | F22: ST | G22: 2.4 | H22: 2.4
C23: Maschinenarbeit | D23: Reifenmontage | E23: 0.15 | F23: STD | G23: 10 | H23: 1.5
C24: Personenarbeit | D24: Reifenmontage | E24: 0.225 | F24: STD | G24: 60 | H24: 13.5
A26: 101228 | B26: Komplettrad 27,5 | H26: 32.68
C27: Reifen 27,5 | D27: =VLOOKUP(C27,Materialstamm!B:H,7,0) -> 101268 | E27: 1 | F27: ST | G27: 4.7 | H27: 4.7
C28: Speichen 27,5 | D28: =VLOOKUP(C28,Materialstamm!B:H,7,0) -> 101283 | E28: 36 | F28: ST | G28: 0.23 | H28: 8.28
C29: Schlauch 27,5 | D29: =VLOOKUP(C29,Materialstamm!B:H,7,0) -> 101273 | E29: 1 | F29: ST | G29: 2.35 | H29: 2.35
C30: Felge 27,5 | D30: =VLOOKUP(C30,Materialstamm!B:H,7,0) -> 101219 | E30: 1 | F30: ST | G30: 2.35 | H30: 2.35
C31: Maschinenarbeit | D31: Reifenmontage | E31: 0.15 | F31: STD | G31: 10 | H31: 1.5
C32: Personenarbeit | D32: Reifenmontage | E32: 0.225 | F32: STD | G32: 60 | H32: 13.5
A34: 101230 | B34: Komplettrad 29 | H34: 34.1
C35: Reifen 29 | D35: =VLOOKUP(C35,Materialstamm!B:H,7,0) -> 101270 | E35: 1 | G35: 5 | H35: 5
C36: Speichen 29 | D36: =VLOOKUP(C36,Materialstamm!B:H,7,0) -> 101285 | E36: 36 | G36: 0.25 | H36: 9
C37: Schlauch 29 | D37: =VLOOKUP(C37,Materialstamm!B:H,7,0) -> 101275 | E37: 1 | G37: 2.6 | H37: 2.6
C38: Felge 29 | D38: =VLOOKUP(C38,Materialstamm!B:H,7,0) -> 101221 | E38: 1 | G38: 2.5 | H38: 2.5
C39: Maschinenarbeit | D39: Reifenmontage | E39: 0.15 | F39: STD | G39: 10 | H39: 1.5
C40: Personenarbeit | D40: Reifenmontage | E40: 0.225 | F40: STD | G40: 60 | H40: 13.5

Sheet bewert. Stücklisten Rahmen
C1: Bez | D1: ArtNr | E1: Menge | F1: ME | G1: Preis | H1: Herstellkosten
A2: 101251 | B2: Rahmen Basic 24 | H2: 148.64
C3: Aluminiumrohr | D3: =VLOOKUP(C3,Materialstamm!B:H,7,0) -> 101215 | E3: 3.2 | F3: =VLOOKUP(D3,Materialstamm!A:F,6,0) -> M | G3: 12.7 | H3: 40.64
C4: Lack | D4: =VLOOKUP(C4,Materialstamm!B:H,7,0) -> 101231 | E4: 0.8 | F4: =VLOOKUP(D4,Materialstamm!A:F,6,0) -> L | G4: 10 | H4: 8
C5: Kettenschaltung Bauteile | D5: =VLOOKUP(C5,Materialstamm!B:H,7,0) -> 101225 | E5: 1 | F5: =VLOOKUP(D5,Materialstamm!A:F,6,0) -> ST | G5: 12 | H5: 12
C6: Kette | D6: =VLOOKUP(C6,Materialstamm!B:H,7,0) -> 101224 | E6: 1 | F6: =VLOOKUP(D6,Materialstamm!A:F,6,0) -> ST | G6: 2 | H6: 2
C7: Bremsanlage | D7: =VLOOKUP(C7,Materialstamm!B:H,7,0) -> 101216 | E7: 1 | F7: =VLOOKUP(D7,Materialstamm!A:F,6,0) -> ST | G7: 16 | H7: 16
C8: Rahmenerstellung | D8: Maschinenarbeit | E8: 0.5 | F8: STD | G8: 26 | H8: 13
C9: Rahmenerstellung | D9: Personalarbeit | E9: 0.95 | F9: STD | G9: 60 | H9: 57
A11: 101252 | B11: Rahmen Basic 26 | H11: 152.18
C12: Aluminiumrohr | D12: =VLOOKUP(C12,Materialstamm!B:H,7,0) -> 101215 | E12: 3.4 | F12: =VLOOKUP(D12,Materialstamm!A:F,6,0) -> M | G12: 12.7 | H12: 43.18
C13: Lack | D13: =VLOOKUP(C13,Materialstamm!B:H,7,0) -> 101231 | E13: 0.9 | F13: =VLOOKUP(D13,Materialstamm!A:F,6,0) -> L | G13: 10 | H13: 9
C14: Kettenschaltung Bauteile | D14: =VLOOKUP(C14,Materialstamm!B:H,7,0) -> 101225 | E14: 1 | F14: =VLOOKUP(D14,Materialstamm!A:F,6,0) -> ST | G14: 12 | H14: 12
C15: Kette | D15: =VLOOKUP(C15,Materialstamm!B:H,7,0) -> 101224 | E15: 1 | F15: =VLOOKUP(D15,Materialstamm!A:F,6,0) -> ST | G15: 2 | H15: 2
C16: Bremsanlage | D16: =VLOOKUP(C16,Materialstamm!B:H,7,0) -> 101216 | E16: 1 | F16: =VLOOKUP(D16,Materialstamm!A:F,6,0) -> ST | G16: 16 | H16: 16
C17: Rahmenerstellung | D17: Maschinenarbeit | E17: 0.5 | F17: STD | G17: 26 | H17: 13
C18: Rahmenerstellung | D18: Personalarbeit | E18: 0.95 | F18: STD | G18: 60 | H18: 57
A20: 101254 | B20: Rahmen Basic 28 | H20: 155.72
C21: Aluminiumrohr | D21: =VLOOKUP(C21,Materialstamm!B:H,7,0) -> 101215 | E21: 3.6 | F21: =VLOOKUP(D21,Materialstamm!A:F,6,0) -> M | G21: 12.7 | H21: 45.72
C22: Lack | D22: =VLOOKUP(C22,Materialstamm!B:H,7,0) -> 101231 | E22: 1 | F22: =VLOOKUP(D22,Materialstamm!A:F,6,0) -> L | G22: 10 | H22: 10
C23: Kettenschaltung Bauteile | D23: =VLOOKUP(C23,Materialstamm!B:H,7,0) -> 101225 | E23: 1 | F23: =VLOOKUP(D23,Materialstamm!A:F,6,0) -> ST | G23: 12 | H23: 12
C24: Kette | D24: =VLOOKUP(C24,Materialstamm!B:H,7,0) -> 101224 | E24: 1 | F24: =VLOOKUP(D24,Materialstamm!A:F,6,0) -> ST | G24: 2 | H24: 2
C25: Bremsanlage | D25: =VLOOKUP(C25,Materialstamm!B:H,7,0) -> 101216 | E25: 1 | F25: =VLOOKUP(D25,Materialstamm!A:F,6,0) -> ST | G25: 16 | H25: 16
C26: Rahmenerstellung | D26: Maschinenarbeit | E26: 0.5 | F26: STD | G26: 26 | H26: 13
C27: Rahmenerstellung | D27: Personalarbeit | E27: 0.95 | F27: STD | G27: 60 | H27: 57
A29: 101253 | B29: Rahmen Basic 27,5 | H29: 154.585
C30: Aluminiumrohr | D30: =VLOOKUP(C30,Materialstamm!B:H,7,0) -> 101215 | E30: 3.55 | F30: =VLOOKUP(D30,Materialstamm!A:F,6,0) -> M | G30: 12.7 | H30: 45.085
C31: Lack | D31: =VLOOKUP(C31,Materialstamm!B:H,7,0) -> 101231 | E31: 0.95 | F31: =VLOOKUP(D31,Materialstamm!A:F,6,0) -> L | G31: 10 | H31: 9.5
C32: Kettenschaltung Bauteile | D32: =VLOOKUP(C32,Materialstamm!B:H,7,0) -> 101225 | E32: 1 | F32: =VLOOKUP(D32,Materialstamm!A:F,6,0) -> ST | G32: 12 | H32: 12
C33: Kette | D33: =VLOOKUP(C33,Materialstamm!B:H,7,0) -> 101224 | E33: 1 | F33: =VLOOKUP(D33,Materialstamm!A:F,6,0) -> ST | G33: 2 | H33: 2
C34: Bremsanlage | D34: =VLOOKUP(C34,Materialstamm!B:H,7,0) -> 101216 | E34: 1 | F34: =VLOOKUP(D34,Materialstamm!A:F,6,0) -> ST | G34: 16 | H34: 16
C35: Rahmenerstellung | D35: Maschinenarbeit | E35: 0.5 | F35: STD | G35: 26 | H35: 13
C36: Rahmenerstellung | D36: Personalarbeit | E36: 0.95 | F36: STD | G36: 60 | H36: 57
A38: 101255 | B38: Rahmen Basic 29 | H38: 159.26
C39: Aluminiumrohr | D39: =VLOOKUP(C39,Materialstamm!B:H,7,0) -> 101215 | E39: 3.8 | F39: =VLOOKUP(D39,Materialstamm!A:F,6,0) -> M | G39: 12.7 | H39: 48.26
C40: Lack | D40: =VLOOKUP(C40,Materialstamm!B:H,7,0) -> 101231 | E40: 1.1 | F40: =VLOOKUP(D40,Materialstamm!A:F,6,0) -> L | G40: 10 | H40: 11
C41: Kettenschaltung Bauteile | D41: =VLOOKUP(C41,Materialstamm!B:H,7,0) -> 101225 | E41: 1 | F41: =VLOOKUP(D41,Materialstamm!A:F,6,0) -> ST | G41: 12 | H41: 12
C42: Kette | D42: =VLOOKUP(C42,Materialstamm!B:H,7,0) -> 101224 | E42: 1 | F42: =VLOOKUP(D42,Materialstamm!A:F,6,0) -> ST | G42: 2 | H42: 2
C43: Bremsanlage | D43: =VLOOKUP(C43,Materialstamm!B:H,7,0) -> 101216 | E43: 1 | F43: =VLOOKUP(D43,Materialstamm!A:F,6,0) -> ST | G43: 16 | H43: 16
C44: Rahmenerstellung | D44: Maschinenarbeit | E44: 0.5 | F44: STD | G44: 26 | H44: 13
...

Sheet bewert. Stücklisten Fahrräder
C1: Bez | D1: ArtNr | E1: Menge | F1: ME | G1: Preis | H1: Herstellkosten
A2: 101236 | B2: Fahrrad Basic 24 | H2: 309.38
C3: Komplettrad 24 | D3: =VLOOKUP(C3,Materialstamm!B:H,7,0) -> 101226 | E3: 2 | F3: =VLOOKUP(D3,Materialstamm!A:F,6,0) -> ST | G3: 30.1 | H3: 60.2
C4: Rahmen Basic 24 | D4: =VLOOKUP(C4,Materialstamm!B:H,7,0) -> 101251 | E4: 1 | F4: =VLOOKUP(D4,Materialstamm!A:F,6,0) -> ST | G4: 148.64 | H4: 148.64
C5: Sechskantmutter 5mm | D5: =VLOOKUP(C5,Materialstamm!B:H,7,0) -> 101276 | E5: 3 | F5: =VLOOKUP(D5,Materialstamm!A:F,6,0) -> ST | G5: 0.01 | H5: 0.03
C6: Sicherungsscheibe 5mm | D6: =VLOOKUP(C6,Materialstamm!B:H,7,0) -> 101277 | E6: 3 | F6: =VLOOKUP(D6,Materialstamm!A:F,6,0) -> ST | G6: 0.01 | H6: 0.03
C7: Inbusschraube 5x20mm | D7: =VLOOKUP(C7,Materialstamm!B:H,7,0) -> 101223 | E7: 4 | F7: =VLOOKUP(D7,Materialstamm!A:F,6,0) -> ST | G7: 0.02 | H7: 0.08
C8: Sitz Bauteile Basic | D8: =VLOOKUP(C8,Materialstamm!B:H,7,0) -> 101278 | E8: 1 | F8: =VLOOKUP(D8,Materialstamm!A:F,6,0) -> ST | G8: 14.6 | H8: 14.6
C9: Lenker Bauteile Basic | D9: =VLOOKUP(C9,Materialstamm!B:H,7,0) -> 101232 | E9: 1 | F9: =VLOOKUP(D9,Materialstamm!A:F,6,0) -> ST | G9: 22.5 | H9: 22.5
C10: Pedale Bauteile | D10: =VLOOKUP(C10,Materialstamm!B:H,7,0) -> 101235 | E10: 1 | F10: =VLOOKUP(D10,Materialstamm!A:F,6,0) -> ST | G10: 8 | H10: 8
C11: Garantiedokument | D11: =VLOOKUP(C11,Materialstamm!B:H,7,0) -> 101222 | E11: 1 | F11: =VLOOKUP(D11,Materialstamm!A:F,6,0) -> ST | G11: 0.3 | H11: 0.3
C12: Fahrradmontage | D12: Maschinenarbeit | E12: 0.25 | F12: STD | G12: 28 | H12: 7
C13: Fahrradmontage | D13: Personalarbeit | E13: 0.8 | F13: STD | G13: 60 | H13: 48
A15: 101237 | B15: Fahrrad Basic 26 | H15: 315.96
C16: Komplettrad 26 | D16: =VLOOKUP(C16,Materialstamm!B:H,7,0) -> 101227 | E16: 2 | F16: =VLOOKUP(D16,Materialstamm!A:F,6,0) -> ST | G16: 31.62 | H16: 63.24
C17: Rahmen Basic 26 | D17: =VLOOKUP(C17,Materialstamm!B:H,7,0) -> 101252 | E17: 1 | F17: =VLOOKUP(D17,Materialstamm!A:F,6,0) -> ST | G17: 152.18 | H17: 152.18
C18: Sechskantmutter 5mm | D18: =VLOOKUP(C18,Materialstamm!B:H,7,0) -> 101276 | E18: 3 | F18: =VLOOKUP(D18,Materialstamm!A:F,6,0) -> ST | G18: 0.01 | H18: 0.03
C19: Sicherungsscheibe 5mm | D19: =VLOOKUP(C19,Materialstamm!B:H,7,0) -> 101277 | E19: 3 | F19: =VLOOKUP(D19,Materialstamm!A:F,6,0) -> ST | G19: 0.01 | H19: 0.03
C20: Inbusschraube 5x20mm | D20: =VLOOKUP(C20,Materialstamm!B:H,7,0) -> 101223 | E20: 4 | F20: =VLOOKUP(D20,Materialstamm!A:F,6,0) -> ST | G20: 0.02 | H20: 0.08
C21: Sitz Bauteile Basic | D21: =VLOOKUP(C21,Materialstamm!B:H,7,0) -> 101278 | E21: 1 | F21: =VLOOKUP(D21,Materialstamm!A:F,6,0) -> ST | G21: 14.6 | H21: 14.6
C22: Lenker Bauteile Basic | D22: =VLOOKUP(C22,Materialstamm!B:H,7,0) -> 101232 | E22: 1 | F22: =VLOOKUP(D22,Materialstamm!A:F,6,0) -> ST | G22: 22.5 | H22: 22.5
C23: Pedale Bauteile | D23: =VLOOKUP(C23,Materialstamm!B:H,7,0) -> 101235 | E23: 1 | F23: =VLOOKUP(D23,Materialstamm!A:F,6,0) -> ST | G23: 8 | H23: 8
C24: Garantiedokument | D24: =VLOOKUP(C24,Materialstamm!B:H,7,0) -> 101222 | E24: 1 | F24: =VLOOKUP(D24,Materialstamm!A:F,6,0) -> ST | G24: 0.3 | H24: 0.3
C25: Fahrradmontage | D25: Maschinenarbeit | E25: 0.25 | F25: STD | G25: 28 | H25: 7
C26: Fahrradmontage | D26: Personalarbeit | E26: 0.8 | F26: STD | G26: 60 | H26: 48
A28: 101239 | B28: Fahrrad Basic 28 | H28: 322.74
C29: Komplettrad 28 | D29: =VLOOKUP(C29,Materialstamm!B:H,7,0) -> 101229 | E29: 2 | F29: =VLOOKUP(D29,Materialstamm!A:F,6,0) -> ST | G29: 33.24 | H29: 66.48
C30: Rahmen Basic 28 | D30: =VLOOKUP(C30,Materialstamm!B:H,7,0) -> 101254 | E30: 1 | F30: =VLOOKUP(D30,Materialstamm!A:F,6,0) -> ST | G30: 155.72 | H30: 155.72
C31: Sechskantmutter 5mm | D31: =VLOOKUP(C31,Materialstamm!B:H,7,0) -> 101276 | E31: 3 | F31: =VLOOKUP(D31,Materialstamm!A:F,6,0) -> ST | G31: 0.01 | H31: 0.03
C32: Sicherungsscheibe 5mm | D32: =VLOOKUP(C32,Materialstamm!B:H,7,0) -> 101277 | E32: 3 | F32: =VLOOKUP(D32,Materialstamm!A:F,6,0) -> ST | G32: 0.01 | H32: 0.03
C33: Inbusschraube 5x20mm | D33: =VLOOKUP(C33,Materialstamm!B:H,7,0) -> 101223 | E33: 4 | F33: =VLOOKUP(D33,Materialstamm!A:F,6,0) -> ST | G33: 0.02 | H33: 0.08
C34: Sitz Bauteile Basic | D34: =VLOOKUP(C34,Materialstamm!B:H,7,0) -> 101278 | E34: 1 | F34: =VLOOKUP(D34,Materialstamm!A:F,6,0) -> ST | G34: 14.6 | H34: 14.6
C35: Lenker Bauteile Basic | D35: =VLOOKUP(C35,Materialstamm!B:H,7,0) -> 101232 | E35: 1 | F35: =VLOOKUP(D35,Materialstamm!A:F,6,0) -> ST | G35: 22.5 | H35: 22.5
C36: Pedale Bauteile | D36: =VLOOKUP(C36,Materialstamm!B:H,7,0) -> 101235 | E36: 1 | F36: =VLOOKUP(D36,Materialstamm!A:F,6,0) -> ST | G36: 8 | H36: 8
C37: Garantiedokument | D37: =VLOOKUP(C37,Materialstamm!B:H,7,0) -> 101222 | E37: 1 | F37: =VLOOKUP(D37,Materialstamm!A:F,6,0) -> ST | G37: 0.3 | H37: 0.3
C38: Fahrradmontage | D38: Maschinenarbeit | E38: 0.25 | F38: STD | G38: 28 | H38: 7
C39: Fahrradmontage | D39: Personalarbeit | E39: 0.8 | F39: STD | G39: 60 | H39: 48
A41: 101238 | B41: Fahrrad Basic 27,5 | H41: 320.485
C42: Komplettrad 27,5 | D42: =VLOOKUP(C42,Materialstamm!B:H,7,0) -> 101228 | E42: 2 | F42: =VLOOKUP(D42,Materialstamm!A:F,6,0) -> ST | G42: 32.68 | H42: 65.36
C43: Rahmen Basic 27,5 | D43: =VLOOKUP(C43,Materialstamm!B:H,7,0) -> 101253 | E43: 1 | F43: =VLOOKUP(D43,Materialstamm!A:F,6,0) -> ST | G43: 154.585 | H43: 154.585
...

Sheet Kostenelemente
C1: MEK | D1: FEK Maschine | E1: FEK Pers | F1: HStK
A2: 101226 | B2: Komplettrad 24 | C2: 15.1 | D2: 1.5 | E2: 13.5 | F2: 30.1
A3: 101227 | B3: Komplettrad 26 | C3: 16.62 | D3: 1.5 | E3: 13.5 | F3: 31.62
A4: 101229 | B4: Komplettrad 28 | C4: 18.24 | D4: 1.5 | E4: 13.5 | F4: 33.24
A5: 101228 | B5: Komplettrad 27,5 | C5: 17.68 | D5: 1.5 | E5: 13.5 | F5: 32.68
A6: 101230 | B6: Komplettrad 29 | C6: 19.1 | D6: 1.5 | E6: 13.5 | F6: 34.1
A7: 101251 | B7: Rahmen Basic 24 | C7: 78.64 | D7: 13 | E7: 57 | F7: 148.64
A8: 101252 | B8: Rahmen Basic 26 | C8: 82.18 | D8: 13 | E8: 57 | F8: 152.18
A9: 101254 | B9: Rahmen Basic 28 | C9: 85.72 | D9: 13 | E9: 57 | F9: 155.72
A10: 101253 | B10: Rahmen Basic 27,5 | C10: 84.585 | D10: 13 | E10: 57 | F10: 154.585
A11: 101255 | B11: Rahmen Basic 29 | C11: 89.26 | D11: 13 | E11: 57 | F11: 159.26
A12: 101256 | B12: Rahmen Comfort 24 | C12: 117.68 | D12: 13 | E12: 57 | F12: 187.68
A13: 101257 | B13: Rahmen Comfort 26 | C13: 123.66 | D13: 13 | E13: 57 | F13: 193.66
... A36: 101250 | B36: Fahrrad Premium 29 | C36: 377.66 | D36: 7 | E36: 48 | F36: 432.66
